Traceback (most recent call last):
  File "/usr/lib/python3/dist-packages/gpiozero/pins/native.py", line 155, in __init__
    self.fd = os.open('/dev/gpiomem', os.O_RDWR | os.O_SYNC)
              ^^^^^^^^^^^^^^^^^^^^^^^^^^^^^^^^^^^^^^^^^^^^^^
FileNotFoundError: [Errno 2] No such file or directory: '/dev/gpiomem'

During handling of the above exception, another exception occurred:

Traceback (most recent call last):
  File "/home/bms/ui_adc.py", line 6, in <module>
    Device.pin_factory = NativeFactory()
                         ^^^^^^^^^^^^^^^
  File "/usr/lib/python3/dist-packages/gpiozero/pins/native.py", line 395, in __init__
    self.mem = GPIOMemory(self.board_info.soc)
               ^^^^^^^^^^^^^^^^^^^^^^^^^^^^^^^
  File "/usr/lib/python3/dist-packages/gpiozero/pins/native.py", line 164, in __init__
    offset = self.gpio_base(soc)
             ^^^^^^^^^^^^^^^^^^^
  File "/usr/lib/python3/dist-packages/gpiozero/pins/native.py", line 192, in gpio_base
    raise IOError('unable to determine gpio base')
OSError: unable to determine gpio base
